Workbook

Sheet COA
A1: COA | F1: Description | G1: BS / IS | H1: D / C | I1: A / NA | L1: A
I2: Whiz | J2: Whiz Prime | K2: Grand Whiz | L2: NA
L3: A/NA | M3: WPKG | N3: WPCC
A4: 1 | F4: ASSETS | G4: BS | H4: D | I4: NA | J4: NA | K4: NA | M4: NA | P4: =CONCATENATE(A4,B4,C4,D4,E4) -> 1
A5: 1 | B5: 1 | F5: Current Assets | G5: BS | H5: D | I5: NA | J5: NA | K5: NA | M5: NA | P5: =CONCATENATE(A5,B5,C5,D5,E5) -> 11
A6: 1 | B6: 1 | C6: 1 | F6: Cash and Cash Equivalent | G6: BS | H6: D | I6: NA | J6: NA | K6: NA | M6: NA | P6: =CONCATENATE(A6,B6,C6,D6,E6) -> 111
A7: 1 | B7: 1 | C7: 1 | D7: 01 | F7: House Bank | G7: BS | H7: D | I7: NA | J7: NA | K7: NA | M7: NA | P7: =CONCATENATE(A7,B7,C7,D7,E7) -> 11101
A8: 1 | B8: 1 | C8: 1 | D8: 01 | E8: 001 | F8: House Bank Main Safe | G8: BS | H8: D | I8: A | J8: A | K8: A | M8: A | P8: =CONCATENATE(A8,B8,C8,D8,E8) -> 11101001 | Q8: =F8 -> House Bank Main Safe
A9: 1 | B9: 1 | C9: 1 | D9: 01 | E9: 002 | F9: House Bank Front Office | G9: BS | H9: D | I9: A | J9: A | K9: A | M9: A | P9: =CONCATENATE(A9,B9,C9,D9,E9) -> 11101002 | Q9: =F9 -> House Bank Front Office
A10: 1 | B10: 1 | C10: 1 | D10: 01 | E10: 003 | F10: House Bank FB | G10: BS | H10: D | I10: NA | J10: A/NA | K10: A | M10: NA | P10: =CONCATENATE(A10,B10,C10,D10,E10) -> 11101003 | Q10: =F10 -> House Bank FB
A11: 1 | B11: 1 | C11: 1 | D11: 01 | E11: 004 | F11: House Bank Spa | G11: BS | H11: D | I11: NA | J11: A/NA | K11: A/NA | M11: NA | P11: =CONCATENATE(A11,B11,C11,D11,E11) -> 11101004 | Q11: =F11 -> House Bank Spa
A12: 1 | B12: 1 | C12: 1 | D12: 01 | E12: 005 | F12: Front Office Cash Clearance | G12: BS | H12: D | I12: A | J12: A | K12: A | L12: temporary account | M12: A | P12: =CONCATENATE(A12,B12,C12,D12,E12) -> 11101005 | Q12: =F12 -> Front Office Cash Clearance
A13: 1 | B13: 1 | C13: 1 | D13: 01 | E13: 006 | F13: Back Office Cash Clearance | G13: BS | H13: D | I13: A | J13: A | K13: A | L13: temporary account | M13: A | P13: =CONCATENATE(A13,B13,C13,D13,E13) -> 11101006 | Q13: =F13 -> Back Office Cash Clearance
A14: 1 | B14: 1 | C14: 1 | D14: 02 | F14: Bank | G14: BS | H14: D | I14: NA | J14: NA | K14: NA | M14: NA | P14: =CONCATENATE(A14,B14,C14,D14,E14) -> 11102 | Q14: =F14 -> Bank
A15: 1 | B15: 1 | C15: 1 | D15: 02 | E15: 001 | F15: Bank In ……………………………… | G15: BS | H15: D | I15: A | J15: A | K15: A | M15: A | P15: =CONCATENATE(A15,B15,C15,D15,E15) -> 11102001 | Q15: =F15 -> Bank In ………………………………
A16: 1 | B16: 1 | C16: 1 | D16: 02 | E16: 002 | F16: Bank In ……………………………… | G16: BS | H16: D | I16: A | J16: A | K16: A | M16: A | P16: =CONCATENATE(A16,B16,C16,D16,E16) -> 11102002 | Q16: =F16 -> Bank In ………………………………
A17: 1 | B17: 1 | C17: 1 | D17: 02 | E17: 003 | F17: Bank Out……………………………… | G17: BS | H17: D | I17: A | J17: A | K17: A | M17: A | P17: =CONCATENATE(A17,B17,C17,D17,E17) -> 11102003 | Q17: =F17 -> Bank Out………………………………
A18: 1 | B18: 1 | C18: 1 | D18: 02 | E18: 004 | F18: Bank Out……………………………… | G18: BS | H18: D | I18: A | J18: A | K18: A | M18: A | P18: =CONCATENATE(A18,B18,C18,D18,E18) -> 11102004 | Q18: =F18 -> Bank Out………………………………
A19: 1 | B19: 1 | C19: 1 | D19: 02 | E19: 005 | F19: Bank FF&E Reserve ……………………………… | G19: BS | H19: D | I19: NA | J19: NA | K19: NA | M19: NA | P19: =CONCATENATE(A19,B19,C19,D19,E19) -> 11102005 | Q19: =F19 -> Bank FF&E Reserve ………………………………
A20: 1 | B20: 1 | C20: 1 | D20: 03 | F20: Time Deposit* | G20: BS | H20: D | I20: NA | J20: NA | K20: NA | M20: NA | P20: =CONCATENATE(A20,B20,C20,D20,E20) -> 11103 | Q20: =F20 -> Time Deposit*
A21: 1 | B21: 1 | C21: 1 | D21: 03 | E21: 001 | F21: Time Deposit | G21: BS | H21: D | I21: A | J21: A | K21: A | M21: A | P21: =CONCATENATE(A21,B21,C21,D21,E21) -> 11103001 | Q21: =F21 -> Time Deposit
A22: 1 | B22: 1 | C22: 2 | F22: Accounts Receivable | G22: BS | H22: D | I22: NA | J22: NA | K22: NA | M22: NA | P22: =CONCATENATE(A22,B22,C22,D22,E22) -> 112 | Q22: =F22 -> Accounts Receivable
A23: 1 | B23: 1 | C23: 2 | D23: 01 | F23: A/R Trade | G23: BS | H23: D | I23: NA | J23: NA | K23: NA | M23: NA | P23: =CONCATENATE(A23,B23,C23,D23,E23) -> 11201 | Q23: =F23 -> A/R Trade
A24: 1 | B24: 1 | C24: 2 | D24: 01 | E24: 001 | F24: A/R Guest Ledger | G24: BS | H24: D | I24: A | J24: A | K24: A | M24: A | P24: =CONCATENATE(A24,B24,C24,D24,E24) -> 11201001 | Q24: =F24 -> A/R Guest Ledger
A25: 1 | B25: 1 | C25: 2 | D25: 01 | E25: 002 | F25: A/R City Ledger Travel | G25: BS | H25: D | I25: A | J25: A | K25: A | M25: A | P25: =CONCATENATE(A25,B25,C25,D25,E25) -> 11201002 | Q25: =F25 -> A/R City Ledger Travel
A26: 1 | B26: 1 | C26: 2 | D26: 01 | E26: 003 | F26: A/R City Ledger Corporate | G26: BS | H26: D | I26: A | J26: A | K26: A | M26: A | P26: =CONCATENATE(A26,B26,C26,D26,E26) -> 11201003 | Q26: =F26 -> A/R City Ledger Corporate
A27: 1 | B27: 1 | C27: 2 | D27: 01 | E27: 004 | F27: A/R City Ledger Government | G27: BS | H27: D | I27: A | J27: A | K27: A | M27: A | P27: =CONCATENATE(A27,B27,C27,D27,E27) -> 11201004 | Q27: =F27 -> A/R City Ledger Government
A28: 1 | B28: 1 | C28: 2 | D28: 01 | E28: 005 | F28: A/R Credit Card Visa BCA | G28: BS | H28: D | I28: A | J28: A | K28: A | M28: A | P28: =CONCATENATE(A28,B28,C28,D28,E28) -> 11201005 | Q28: =F28 -> A/R Credit Card Visa BCA
A29: 1 | B29: 1 | C29: 2 | D29: 01 | E29: 006 | F29: A/R Credit Card Master BCA | G29: BS | H29: D | I29: A | J29: A | K29: A | M29: A | P29: =CONCATENATE(A29,B29,C29,D29,E29) -> 11201006 | Q29: =F29 -> A/R Credit Card Master BCA
A30: 1 | B30: 1 | C30: 2 | D30: 01 | E30: 007 | F30: A/R BCA Card | G30: BS | H30: D | I30: A | J30: A | K30: A | M30: A | P30: =CONCATENATE(A30,B30,C30,D30,E30) -> 11201007 | Q30: =F30 -> A/R BCA Card
A31: 1 | B31: 1 | C31: 2 | D31: 01 | E31: 008 | F31: A/R Credit Card Visa Mandiri | G31: BS | H31: D | I31: A | J31: A | K31: A | M31: A | P31: =CONCATENATE(A31,B31,C31,D31,E31) -> 11201008 | Q31: =F31 -> A/R Credit Card Visa Mandiri
A32: 1 | B32: 1 | C32: 2 | D32: 01 | E32: 009 | F32: A/R Credit Card Master Mandiri | G32: BS | H32: D | I32: A | J32: A | K32: A | M32: A | P32: =CONCATENATE(A32,B32,C32,D32,E32) -> 11201009 | Q32: =F32 -> A/R Credit Card Master Mandiri
A33: 1 | B33: 1 | C33: 2 | D33: 01 | E33: 010 | F33: A/R Credit Card Visa Other | G33: BS | H33: D | I33: A | J33: A | K33: A | M33: A | P33: =CONCATENATE(A33,B33,C33,D33,E33) -> 11201010 | Q33: =F33 -> A/R Credit Card Visa Other
A34: 1 | B34: 1 | C34: 2 | D34: 01 | E34: 011 | F34: A/R Credit Card Master Other | G34: BS | H34: D | I34: A | J34: A | K34: A | M34: A | P34: =CONCATENATE(A34,B34,C34,D34,E34) -> 11201011 | Q34: =F34 -> A/R Credit Card Master Other
A35: 1 | B35: 1 | C35: 2 | D35: 01 | E35: 012 | F35: Pre Account Receiveable | G35: BS | H35: D | I35: A | J35: A | K35: A | L35: temporary account | M35: A | P35: =CONCATENATE(A35,B35,C35,D35,E35) -> 11201012 | Q35: =F35 -> Pre Account Receiveable
A36: 1 | B36: 1 | C36: 2 | D36: 01 | E36: 013 | F36: Pre Credit Card | G36: BS | H36: D | I36: A | J36: A | K36: A | L36: temporary account | M36: A | P36: =CONCATENATE(A36,B36,C36,D36,E36) -> 11201013 | Q36: =F36 -> Pre Credit Card
A37: 1 | B37: 1 | C37: 2 | D37: 03 | F37: A/R Affiliate | G37: BS | H37: D | I37: NA | J37: NA | K37: NA | M37: NA | P37: =CONCATENATE(A37,B37,C37,D37,E37) -> 11203 | Q37: =F37 -> A/R Affiliate
A38: 1 | B38: 1 | C38: 2 | D38: 03 | E38: 001 | F38: A/R Affiliated PT. …………………………… | G38: BS | H38: D | I38: A | J38: A | K38: A | M38: A | P38: =CONCATENATE(A38,B38,C38,D38,E38) -> 11203001 | Q38: =F38 -> A/R Affiliated PT. ……………………………
A39: 1 | B39: 1 | C39: 2 | D39: 03 | E39: 002 | F39: A/R Affiliated PT. …………………………… | G39: BS | H39: D | I39: A | J39: A | K39: A | M39: A | P39: =CONCATENATE(A39,B39,C39,D39,E39) -> 11203002 | Q39: =F39 -> A/R Affiliated PT. ……………………………
A40: 1 | B40: 1 | C40: 2 | D40: 04 | F40: Other Receivable | G40: BS | H40: D | I40: NA | J40: NA | K40: NA | M40: NA | P40: =CONCATENATE(A40,B40,C40,D40,E40) -> 11204 | Q40: =F40 -> Other Receivable
...

Sheet COA (2)
A1: COA | F1: Description | G1: BS / IS | H1: D / C | I1: A / NA | L1: A
I2: Whiz | J2: Whiz Prime | K2: Grand Whiz | L2: NA
L3: A/NA | M3: WPKG | N3: WPCC
A4: 1 | F4: ASSETS | G4: BS | H4: D | I4: NA | J4: NA | K4: NA | M4: NA
A5: 1 | B5: 1 | F5: Current Assets | G5: BS | H5: D | I5: NA | J5: NA | K5: NA | M5: NA
A6: 1 | B6: 1 | C6: 1 | F6: Cash and Cash Equivalent | G6: BS | H6: D | I6: NA | J6: NA | K6: NA | M6: NA
A7: 1 | B7: 1 | C7: 1 | D7: 01 | F7: House Bank | G7: BS | H7: D | I7: NA | J7: NA | K7: NA | M7: NA
A8: 1 | B8: 1 | C8: 1 | D8: 01 | E8: 001 | F8: House Bank Main Safe | G8: BS | H8: D | I8: A | J8: A | K8: A | M8: A | P8: =CONCATENATE(A8,B8,C8,D8,E8) -> 11101001 | Q8: =F8 -> House Bank Main Safe
A9: 1 | B9: 1 | C9: 1 | D9: 01 | E9: 002 | F9: House Bank Front Office | G9: BS | H9: D | I9: A | J9: A | K9: A | M9: A | P9: =CONCATENATE(A9,B9,C9,D9,E9) -> 11101002 | Q9: =F9 -> House Bank Front Office
A10: 1 | B10: 1 | C10: 1 | D10: 01 | E10: 003 | F10: House Bank FB | G10: BS | H10: D | I10: NA | J10: A/NA | K10: A | M10: NA | P10: =CONCATENATE(A10,B10,C10,D10,E10) -> 11101003 | Q10: =F10 -> House Bank FB
A11: 1 | B11: 1 | C11: 1 | D11: 01 | E11: 004 | F11: House Bank Spa | G11: BS | H11: D | I11: NA | J11: A/NA | K11: A/NA | M11: NA | P11: =CONCATENATE(A11,B11,C11,D11,E11) -> 11101004 | Q11: =F11 -> House Bank Spa
A12: 1 | B12: 1 | C12: 1 | D12: 01 | E12: 005 | F12: Front Office Cash Clearance | G12: BS | H12: D | I12: A | J12: A | K12: A | L12: temporary account | M12: A | P12: =CONCATENATE(A12,B12,C12,D12,E12) -> 11101005 | Q12: =F12 -> Front Office Cash Clearance
A13: 1 | B13: 1 | C13: 1 | D13: 01 | E13: 006 | F13: Back Office Cash Clearance | G13: BS | H13: D | I13: A | J13: A | K13: A | L13: temporary account | M13: A | P13: =CONCATENATE(A13,B13,C13,D13,E13) -> 11101006 | Q13: =F13 -> Back Office Cash Clearance
A14: 1 | B14: 1 | C14: 1 | D14: 02 | F14: Bank | G14: BS | H14: D | I14: NA | J14: NA | K14: NA | M14: NA
A15: 1 | B15: 1 | C15: 1 | D15: 02 | E15: 001 | F15: Bank In ……………………………… | G15: BS | H15: D | I15: A | J15: A | K15: A | M15: A | P15: =CONCATENATE(A15,B15,C15,D15,E15) -> 11102001 | Q15: =F15 -> Bank In ………………………………
A16: 1 | B16: 1 | C16: 1 | D16: 02 | E16: 002 | F16: Bank In ……………………………… | G16: BS | H16: D | I16: A | J16: A | K16: A | M16: A | P16: =CONCATENATE(A16,B16,C16,D16,E16) -> 11102002 | Q16: =F16 -> Bank In ………………………………
A17: 1 | B17: 1 | C17: 1 | D17: 02 | E17: 003 | F17: Bank Out……………………………… | G17: BS | H17: D | I17: A | J17: A | K17: A | M17: A | P17: =CONCATENATE(A17,B17,C17,D17,E17) -> 11102003 | Q17: =F17 -> Bank Out………………………………
A18: 1 | B18: 1 | C18: 1 | D18: 02 | E18: 004 | F18: Bank Out……………………………… | G18: BS | H18: D | I18: A | J18: A | K18: A | M18: A | P18: =CONCATENATE(A18,B18,C18,D18,E18) -> 11102004 | Q18: =F18 -> Bank Out………………………………
A19: 1 | B19: 1 | C19: 1 | D19: 02 | E19: 005 | F19: Bank FF&E Reserve ……………………………… | G19: BS | H19: D | I19: NA | J19: NA | K19: NA | M19: NA | P19: =CONCATENATE(A19,B19,C19,D19,E19) -> 11102005 | Q19: =F19 -> Bank FF&E Reserve ………………………………
A20: 1 | B20: 1 | C20: 1 | D20: 03 | F20: Time Deposit* | G20: BS | H20: D | I20: NA | J20: NA | K20: NA | M20: NA
A21: 1 | B21: 1 | C21: 1 | D21: 03 | E21: 001 | F21: Time Deposit | G21: BS | H21: D | I21: A | J21: A | K21: A | M21: A | P21: =CONCATENATE(A21,B21,C21,D21,E21) -> 11103001 | Q21: =F21 -> Time Deposit
A22: 1 | B22: 1 | C22: 2 | F22: Accounts Receivable | G22: BS | H22: D | I22: NA | J22: NA | K22: NA | M22: NA
A23: 1 | B23: 1 | C23: 2 | D23: 01 | F23: A/R Trade | G23: BS | H23: D | I23: NA | J23: NA | K23: NA | M23: NA
A24: 1 | B24: 1 | C24: 2 | D24: 01 | E24: 001 | F24: A/R Guest Ledger | G24: BS | H24: D | I24: A | J24: A | K24: A | M24: A | P24: =CONCATENATE(A24,B24,C24,D24,E24) -> 11201001 | Q24: =F24 -> A/R Guest Ledger
A25: 1 | B25: 1 | C25: 2 | D25: 01 | E25: 002 | F25: A/R City Ledger Travel | G25: BS | H25: D | I25: A | J25: A | K25: A | M25: A | P25: =CONCATENATE(A25,B25,C25,D25,E25) -> 11201002 | Q25: =F25 -> A/R City Ledger Travel
A26: 1 | B26: 1 | C26: 2 | D26: 01 | E26: 003 | F26: A/R City Ledger Corporate | G26: BS | H26: D | I26: A | J26: A | K26: A | M26: A | P26: =CONCATENATE(A26,B26,C26,D26,E26) -> 11201003 | Q26: =F26 -> A/R City Ledger Corporate
A27: 1 | B27: 1 | C27: 2 | D27: 01 | E27: 004 | F27: A/R City Ledger Government | G27: BS | H27: D | I27: A | J27: A | K27: A | M27: A | P27: =CONCATENATE(A27,B27,C27,D27,E27) -> 11201004 | Q27: =F27 -> A/R City Ledger Government
A28: 1 | B28: 1 | C28: 2 | D28: 01 | E28: 005 | F28: A/R Credit Card Visa BCA | G28: BS | H28: D | I28: A | J28: A | K28: A | M28: A | P28: =CONCATENATE(A28,B28,C28,D28,E28) -> 11201005 | Q28: =F28 -> A/R Credit Card Visa BCA
A29: 1 | B29: 1 | C29: 2 | D29: 01 | E29: 006 | F29: A/R Credit Card Master BCA | G29: BS | H29: D | I29: A | J29: A | K29: A | M29: A | P29: =CONCATENATE(A29,B29,C29,D29,E29) -> 11201006 | Q29: =F29 -> A/R Credit Card Master BCA
A30: 1 | B30: 1 | C30: 2 | D30: 01 | E30: 007 | F30: A/R BCA Card | G30: BS | H30: D | I30: A | J30: A | K30: A | M30: A | P30: =CONCATENATE(A30,B30,C30,D30,E30) -> 11201007 | Q30: =F30 -> A/R BCA Card
A31: 1 | B31: 1 | C31: 2 | D31: 01 | E31: 008 | F31: A/R Credit Card Visa Mandiri | G31: BS | H31: D | I31: A | J31: A | K31: A | M31: A | P31: =CONCATENATE(A31,B31,C31,D31,E31) -> 11201008 | Q31: =F31 -> A/R Credit Card Visa Mandiri
A32: 1 | B32: 1 | C32: 2 | D32: 01 | E32: 009 | F32: A/R Credit Card Master Mandiri | G32: BS | H32: D | I32: A | J32: A | K32: A | M32: A | P32: =CONCATENATE(A32,B32,C32,D32,E32) -> 11201009 | Q32: =F32 -> A/R Credit Card Master Mandiri
A33: 1 | B33: 1 | C33: 2 | D33: 01 | E33: 010 | F33: A/R Credit Card Visa Other | G33: BS | H33: D | I33: A | J33: A | K33: A | M33: A | P33: =CONCATENATE(A33,B33,C33,D33,E33) -> 11201010 | Q33: =F33 -> A/R Credit Card Visa Other
A34: 1 | B34: 1 | C34: 2 | D34: 01 | E34: 011 | F34: A/R Credit Card Master Other | G34: BS | H34: D | I34: A | J34: A | K34: A | M34: A | P34: =CONCATENATE(A34,B34,C34,D34,E34) -> 11201011 | Q34: =F34 -> A/R Credit Card Master Other
A35: 1 | B35: 1 | C35: 2 | D35: 01 | E35: 012 | F35: Pre Account Receiveable | G35: BS | H35: D | I35: A | J35: A | K35: A | L35: temporary account | M35: A | P35: =CONCATENATE(A35,B35,C35,D35,E35) -> 11201012 | Q35: =F35 -> Pre Account Receiveable
A36: 1 | B36: 1 | C36: 2 | D36: 01 | E36: 013 | F36: Pre Credit Card | G36: BS | H36: D | I36: A | J36: A | K36: A | L36: temporary account | M36: A | P36: =CONCATENATE(A36,B36,C36,D36,E36) -> 11201013 | Q36: =F36 -> Pre Credit Card
A37: 1 | B37: 1 | C37: 2 | D37: 03 | F37: A/R Affiliate | G37: BS | H37: D | I37: NA | J37: NA | K37: NA | M37: NA
A38: 1 | B38: 1 | C38: 2 | D38: 03 | E38: 001 | F38: A/R Affiliated PT. …………………………… | G38: BS | H38: D | I38: A | J38: A | K38: A | M38: A | P38: =CONCATENATE(A38,B38,C38,D38,E38) -> 11203001 | Q38: =F38 -> A/R Affiliated PT. ……………………………
A39: 1 | B39: 1 | C39: 2 | D39: 03 | E39: 002 | F39: A/R Affiliated PT. …………………………… | G39: BS | H39: D | I39: A | J39: A | K39: A | M39: A | P39: =CONCATENATE(A39,B39,C39,D39,E39) -> 11203002 | Q39: =F39 -> A/R Affiliated PT. ……………………………
A40: 1 | B40: 1 | C40: 2 | D40: 04 | F40: Other Receivable | G40: BS | H40: D | I40: NA | J40: NA | K40: NA | M40: NA
...

Sheet Prepaid Exp
A1: PT.
A2: Prepaid Expense
A3: For the month ended
A5: No | B5: Quantity | C5: Start | E5: End | G5: Descriptions | H5: Useful Life Time | J5: Prepaid | K5: Amort Exp | L5: Acc Amort | M5: Net Book Value | N5: Amort Exp 2013 | Z5: Acc Amort | AA5: Net Book Value | AB5: Voucher Number
C6: Year | D6: Month | E6: Year | F6: Month | K6: / Month | L6: Last Year | M6: 41275 | N6: 41275 | O6: 41306 | P6: 41334 | Q6: 41365 | R6: 41395 | S6: 41426 | T6: 41456 | U6: 41487 | V6: 41518 | W6: 41548 | X6: 41579 | Y6: 41609 | Z6: YTD | AA6: 41639
D7: 1-12 | F7: 1-12 | H7: Y | I7: M
A8: MANUAL | I8: RUMUS | J8: MANUAL | K8: RUMUS | L8: MANUAL | M8: RUMUS | N8: RUMUS | O8: RUMUS | P8: RUMUS | Q8: RUMUS | R8: RUMUS | S8: RUMUS | T8: RUMUS | U8: RUMUS | V8: RUMUS | W8: RUMUS | X8: RUMUS | Y8: RUMUS | Z8: RUMUS | AA8: RUMUS | AB8: MANUAL
A10: 1 | B10: 1 | C10: 2012 | D10: 9.0000007 | E10: 2013 | F10: 8 | G10: Insurance | H10: 1 | I10: =+H10*12 -> 12 | J10: 20683386 | K10: =J10/I10 -> 1723615.5 | L10: =4*K10 -> 6894462.1 | M10: =J10-L10 -> 13788924 | N10: =$K$10 -> 1723615.5 | O10: =$K$10 -> 1723615.5 | P10: =$K$10 -> 1723615.5 | Q10: =$K$10 -> 1723615.5 | R10: =$K$10 -> 1723615.5 | S10: =$K$10 -> 1723615.5 | T10: =$K$10 -> 1723615.5 | U10: =$K$10 -> 1723615.5 | Z10: =L10+N10+O10+P10+Q10+R10+S10+T10+U10+V10+W10+X10+Y10 -> 20683386 | AA10: =M10-N10-O10-P10-Q10-R10-S10-T10-U10-V10-W10-X10-Y10 -> 0 | AB10: VMJ 08.014-04
A11: 2 | B11: 1 | C11: 2012 | D11: 9.0000007 | E11: 2014 | F11: 8 | G11: Advertising | H11: 2 | I11: =+H11*12 -> 24 | J11: 945000 | K11: =J11/I11 -> 39375 | L11: =4*K11 -> 157500 | M11: =J11-L11 -> 787500 | N11: =$K$11 -> 39375 | O11: =$K$11 -> 39375 | P11: =$K$11 -> 39375 | Q11: =$K$11 -> 39375 | R11: =$K$11 -> 39375 | S11: =$K$11 -> 39375 | T11: =$K$11 -> 39375 | U11: =$K$11 -> 39375 | ... Y11: =$K$11 -> 39375 | Z11: =L11+N11+O11+P11+Q11+R11+S11+T11+U11+V11+W11+X11+Y11 -> 630000 | AA11: =M11-N11-O11-P11-Q11-R11-S11-T11-U11-V11-W11-X11-Y11 -> 315000 | AB11: TT/01026/06/V
A12: 3 | B12: 1 | C12: 2012 | D12: 9.0000007 | E12: 2013 | F12: 8 | G12: License | H12: 1 | I12: =+H12*12 -> 12 | J12: 13688227 | K12: =J12/I12 -> 1140685.6 | L12: =4*K12 -> 4562742.4 | M12: =J12-L12 -> 9125484.9 | N12: =$K$12 -> 1140685.6 | O12: =$K$12 -> 1140685.6 | P12: =$K$12 -> 1140685.6 | Q12: =$K$12 -> 1140685.6 | R12: =$K$12 -> 1140685.6 | S12: =$K$12 -> 1140685.6 | T12: =$K$12 -> 1140685.6 | U12: =$K$12 -> 1140685.6 | Z12: =L12+N12+O12+P12+Q12+R12+S12+T12+U12+V12+W12+X12+Y12 -> 13688227 | AA12: =M12-N12-O12-P12-Q12-R12-S12-T12-U12-V12-W12-X12-Y12 -> 0 | AB12: TT/04019/07/V
A13: 4 | B13: 1 | C13: 2012 | D13: 9.0000007 | E13: 2014 | F13: 8 | G13: Insurance | H13: 2 | I13: =+H13*12 -> 24 | J13: 23406091 | K13: =J13/I13 -> 975253.79 | L13: =4*K13 -> 3901015.1 | M13: =J13-L13 -> 19505076 | N13: =$K$13 -> 975253.79 | O13: =$K$13 -> 975253.79 | P13: =$K$13 -> 975253.79 | Q13: =$K$13 -> 975253.79 | R13: =$K$13 -> 975253.79 | S13: =$K$13 -> 975253.79 | T13: =$K$13 -> 975253.79 | U13: =$K$13 -> 975253.79 | ... Y13: =$K$13 -> 975253.79 | Z13: =L13+N13+O13+P13+Q13+R13+S13+T13+U13+V13+W13+X13+Y13 -> 15604061 | AA13: =M13-N13-O13-P13-Q13-R13-S13-T13-U13-V13-W13-X13-Y13 -> 7802030.3 | AB13: TT/06030/07/V
A14: 5 | B14: 1 | C14: 2012 | D14: 9.0000007 | E14: 2013 | F14: 8 | G14: Advertising | H14: 1 | I14: =+H14*12 -> 12 | J14: 13055318 | K14: =J14/I14 -> 1087943.2 | L14: =4*K14 -> 4351772.7 | M14: =J14-L14 -> 8703545.5 | N14: =$K$14 -> 1087943.2 | O14: =$K$14 -> 1087943.2 | P14: =$K$14 -> 1087943.2 | Q14: =$K$14 -> 1087943.2 | R14: =$K$14 -> 1087943.2 | S14: =$K$14 -> 1087943.2 | T14: =$K$14 -> 1087943.2 | U14: =$K$14 -> 1087943.2 | Z14: =L14+N14+O14+P14+Q14+R14+S14+T14+U14+V14+W14+X14+Y14 -> 13055318 | AA14: =M14-N14-O14-P14-Q14-R14-S14-T14-U14-V14-W14-X14-Y14 -> -3.259629e-09 | AB14: TT/12029/07/V
A15: 6 | B15: 1 | C15: 2012 | D15: 9.0000007 | E15: 2014 | F15: 8 | G15: License | H15: 2 | I15: =+H15*12 -> 24 | J15: 982409.1 | K15: =J15/I15 -> 40933.713 | L15: =4*K15 -> 163734.85 | M15: =J15-L15 -> 818674.25 | N15: =$K$15 -> 40933.713 | O15: =$K$15 -> 40933.713 | P15: =$K$15 -> 40933.713 | Q15: =$K$15 -> 40933.713 | R15: =$K$15 -> 40933.713 | S15: =$K$15 -> 40933.713 | T15: =$K$15 -> 40933.713 | U15: =$K$15 -> 40933.713 | ... Y15: =$K$15 -> 40933.713 | Z15: =L15+N15+O15+P15+Q15+R15+S15+T15+U15+V15+W15+X15+Y15 -> 654939.4 | AA15: =M15-N15-O15-P15-Q15-R15-S15-T15-U15-V15-W15-X15-Y15 -> 327469.7 | AB15: TT/04034/08/V
A16: 7 | B16: 1 | C16: 2012 | D16: 9.0000007 | E16: 2013 | F16: 8 | G16: Insurance | H16: 1 | I16: =+H16*12 -> 12 | J16: 25179318 | K16: =J16/I16 -> 2098276.5 | L16: =4*K16 -> 8393106.1 | M16: =J16-L16 -> 16786212 | N16: =$K$16 -> 2098276.5 | O16: =$K$16 -> 2098276.5 | P16: =$K$16 -> 2098276.5 | Q16: =$K$16 -> 2098276.5 | R16: =$K$16 -> 2098276.5 | S16: =$K$16 -> 2098276.5 | T16: =$K$16 -> 2098276.5 | U16: =$K$16 -> 2098276.5 | Z16: =L16+N16+O16+P16+Q16+R16+S16+T16+U16+V16+W16+X16+Y16 -> 25179318 | AA16: =M16-N16-O16-P16-Q16-R16-S16-T16-U16-V16-W16-X16-Y16 -> 3.7252903e-09 | AB16: TT/07019/08/V
A17: 8 | B17: 1 | C17: 2012 | D17: 9.0000007 | E17: 2014 | F17: 8 | G17: Advertising | H17: 2 | I17: =+H17*12 -> 24 | J17: 16542409 | K17: =J17/I17 -> 689267.05 | L17: =4*K17 -> 2757068.2 | M17: =J17-L17 -> 13785341 | N17: =$K$17 -> 689267.05 | O17: =$K$17 -> 689267.05 | P17: =$K$17 -> 689267.05 | Q17: =$K$17 -> 689267.05 | R17: =$K$17 -> 689267.05 | S17: =$K$17 -> 689267.05 | T17: =$K$17 -> 689267.05 | U17: =$K$17 -> 689267.05 | ... Y17: =$K$17 -> 689267.05 | Z17: =L17+N17+O17+P17+Q17+R17+S17+T17+U17+V17+W17+X17+Y17 -> 11028273 | AA17: =M17-N17-O17-P17-Q17-R17-S17-T17-U17-V17-W17-X17-Y17 -> 5514136.4 | AB17: IV/11012/09/V
A18: 9 | B18: 1 | C18: 2012 | D18: 9.0000007 | E18: 2013 | F18: 8 | G18: License | H18: 1 | I18: =+H18*12 -> 12 | J18: 24495046 | K18: =J18/I18 -> 2041253.8 | L18: =4*K18 -> 8165015.2 | M18: =J18-L18 -> 16330030 | N18: =$K$18 -> 2041253.8 | O18: =$K$18 -> 2041253.8 | P18: =$K$18 -> 2041253.8 | Q18: =$K$18 -> 2041253.8 | R18: =$K$18 -> 2041253.8 | S18: =$K$18 -> 2041253.8 | T18: =$K$18 -> 2041253.8 | U18: =$K$18 -> 2041253.8 | Z18: =L18+N18+O18+P18+Q18+R18+S18+T18+U18+V18+W18+X18+Y18 -> 24495046 | AA18: =M18-N18-O18-P18-Q18-R18-S18-T18-U18-V18-W18-X18-Y18 -> -4.6566129e-10 | AB18: IV/11012/09/V
A19: 10 | B19: 1 | C19: 2012 | D19: 9.0000007 | E19: 2014 | F19: 8 | G19: Insurance | H19: 2 | I19: =+H19*12 -> 24 | J19: 14459227 | K19: =J19/I19 -> 602467.8 | L19: =4*K19 -> 2409871.2 | M19: =J19-L19 -> 12049356 | N19: =$K$19 -> 602467.8 | O19: =$K$19 -> 602467.8 | P19: =$K$19 -> 602467.8 | Q19: =$K$19 -> 602467.8 | R19: =$K$19 -> 602467.8 | S19: =$K$19 -> 602467.8 | T19: =$K$19 -> 602467.8 | U19: =$K$19 -> 602467.8 | ... Y19: =$K$19 -> 602467.8 | Z19: =L19+N19+O19+P19+Q19+R19+S19+T19+U19+V19+W19+X19+Y19 -> 9639484.9 | AA19: =M19-N19-O19-P19-Q19-R19-S19-T19-U19-V19-W19-X19-Y19 -> 4819742.4 | AB19: IV/09018/10/V
A20: 11 | B20: 1 | C20: 2012 | D20: 9.0000007 | E20: 2013 | F20: 8 | G20: Advertising | H20: 1 | I20: =+H20*12 -> 12 | J20: 13140273 | K20: =J20/I20 -> 1095022.7 | L20: =4*K20 -> 4380090.9 | M20: =J20-L20 -> 8760181.8 | N20: =$K$20 -> 1095022.7 | O20: =$K$20 -> 1095022.7 | P20: =$K$20 -> 1095022.7 | Q20: =$K$20 -> 1095022.7 | R20: =$K$20 -> 1095022.7 | S20: =$K$20 -> 1095022.7 | T20: =$K$20 -> 1095022.7 | U20: =$K$20 -> 1095022.7 | Z20: =L20+N20+O20+P20+Q20+R20+S20+T20+U20+V20+W20+X20+Y20 -> 13140273 | AA20: =M20-N20-O20-P20-Q20-R20-S20-T20-U20-V20-W20-X20-Y20 -> 3.259629e-09 | AB20: TT/12015/10/V
A22: =CONCATENATE("TOTAL ",$B$7) -> TOTAL | J22: =SUM(J10:J21) -> 1.665767e+08 | K22: =SUM(K10:K21) -> 11534095 | L22: =SUM(L10:L21) -> 46136379 | M22: =SUM(M10:M21) -> 1.2044033e+08 | N22: =SUM(N10:N21) -> 11534095 | O22: =SUM(O10:O21) -> 11534095 | P22: =SUM(P10:P21) -> 11534095 | Q22: =SUM(Q10:Q21) -> 11534095 | ... Y22: =SUM(Y10:Y21) -> 2347297.4 | Z22: =SUM(Z10:Z20) -> 1.4779833e+08 | AA22: =SUM(AA10:AA21) -> 18778379

Sheet Inventory
A1: PT.
A2: Inventory
A3: For the month ended
A5: No | B5: Item | C5: Cost / Unit | D5: Quantity | H5: Inventory
D6: Beginning | E6: Purchase | F6: Loss | G6: Ending
A8: 1 | B8: BS(100x200+30cm Fitted,100% Catton,200TC) | C8: 130000 | D8: 100 | E8: 100 | F8: 100 | G8: =D8+E8-F8 -> 100 | H8: =C8*G8 -> 13000000
B9: BS(100x200+30cm Fitted,100% Catton,200TC) | C9: 150000 | D9: 50 | E9: 50 | F9: 50 | G9: =D9+E9-F9 -> 50 | H9: =C9*G9 -> 7500000
A10: 2 | B10: BD(180x200+30cm Fitted,100% Catton) | C10: 110000 | D10: 40 | E10: 40 | F10: 40 | G10: =D10+E10-F10 -> 40 | H10: =C10*G10 -> 4400000
B11: BD(180x200+30cm Fitted,100% Catton) | C11: 130000 | D11: 50 | E11: 50 | F11: 50 | G11: =D11+E11-F11 -> 50 | H11: =C11*G11 -> 6500000
G12: =D12+E12-F12 -> 0 | H12: =C12*G12 -> 0
G13: =D13+E13-F13 -> 0 | H13: =C13*G13 -> 0
G14: =D14+E14-F14 -> 0 | H14: =C14*G14 -> 0
G15: =D15+E15-F15 -> 0 | H15: =C15*G15 -> 0
G16: =D16+E16-F16 -> 0 | H16: =C16*G16 -> 0
G17: =D17+E17-F17 -> 0 | H17: =C17*G17 -> 0
G18: =D18+E18-F18 -> 0 | H18: =C18*G18 -> 0
G19: =D19+E19-F19 -> 0 | H19: =C19*G19 -> 0
G20: =D20+E20-F20 -> 0 | H20: =C20*G20 -> 0
G21: =D21+E21-F21 -> 0 | H21: =C21*G21 -> 0
G22: =D22+E22-F22 -> 0 | H22: =C22*G22 -> 0
G23: =D23+E23-F23 -> 0 | H23: =C23*G23 -> 0
... G25: =D25+E25-F25 -> 0 | H25: =C25*G25 -> 0
D26: =SUM(D7:D25) -> 240 | E26: =SUM(E7:E25) -> 240 | F26: =SUM(F7:F25) -> 240 | G26: =SUM(G7:G25) -> 240 | H26: =SUM(H7:H25) -> 31400000
B28: tinggal add comment untuk setiap pembelian dan penghapusan

Sheet FA
A1: PT.
A2: (Fixed and Intangible Asset)
A3: For the month ended
A5: No | B5: Quantity | C5: Purchase | E5: Disposal | G5: Descriptions | H5: Useful Life Time | J5: Cost | K5: Depr Exp | L5: Acc Depr | M5: Net Book Value | N5: Depr Exp 2013 | Z5: Acc Depr | AA5: Net Book Value | AB5: Voucher Number | AC5: Location | AD5: Code
C6: Year | D6: Month | E6: Year | F6: Month | K6: / Month | L6: Last Year | M6: 41275 | N6: 41275 | O6: 41306 | P6: 41334 | Q6: 41365 | R6: 41395 | S6: 41426 | T6: 41456 | U6: 41487 | V6: 41518 | W6: 41548 | X6: 41579 | Y6: 41609 | Z6: YTD | AA6: 41639
D7: 1-12 | F7: 1-12 | H7: Y | I7: M
A8: MANUAL | I8: RUMUS | J8: MANUAL | K8: RUMUS | L8: MANUAL | M8: RUMUS | N8: RUMUS | O8: RUMUS | P8: RUMUS | Q8: RUMUS | R8: RUMUS | S8: RUMUS | T8: RUMUS | U8: RUMUS | V8: RUMUS | W8: RUMUS | X8: RUMUS | Y8: RUMUS | Z8: RUMUS | AA8: RUMUS | AB8: MANUAL
AF9: Unit | AG9: Asset | AI9: Dept | AK9: MM/YY | AM9: No Asset
A10: 1 | B10: 1 | C10: 2012 | D10: 9.0000007 | G10: Nissan | H10: 8 | I10: =+H10*12 -> 96 | J10: 206833864 | K10: =J10/I10 -> 2154519.4 | L10: 8618077.7 | M10: =J10-L10 -> 1.9821579e+08 | N10: =$K$10 -> 2154519.4 | O10: =$K$10 -> 2154519.4 | P10: =$K$10 -> 2154519.4 | Q10: =$K$10 -> 2154519.4 | R10: =$K$10 -> 2154519.4 | S10: =$K$10 -> 2154519.4 | T10: =$K$10 -> 2154519.4 | U10: =$K$10 -> 2154519.4 | ... Y10: =$K$10 -> 2154519.4 | Z10: =L10+N10+O10+P10+Q10+R10+S10+T10+U10+V10+W10+X10+Y10 -> 34472311 | AA10: =M10-N10-O10-P10-Q10-R10-S10-T10-U10-V10-W10-X10-Y10 -> 1.7236155e+08 | AB10: VMJ 08.014-04 | AC10: Jual ke PHK 3 | AD10: COL.FO.1013.0001
A11: 2 | B11: 1 | C11: 2012 | D11: 9.0000007 | G11: Suzuki | H11: 4 | I11: =+H11*12 -> 48 | J11: 9450000 | K11: =J11/I11 -> 196875 | L11: 787500 | M11: =J11-L11 -> 8662500 | N11: =$K$11 -> 196875 | O11: =$K$11 -> 196875 | P11: =$K$11 -> 196875 | Q11: =$K$11 -> 196875 | R11: =$K$11 -> 196875 | S11: =$K$11 -> 196875 | T11: =$K$11 -> 196875 | U11: =$K$11 -> 196875 | ... Y11: =$K$11 -> 196875 | Z11: =L11+N11+O11+P11+Q11+R11+S11+T11+U11+V11+W11+X11+Y11 -> 3150000 | AA11: =M11-N11-O11-P11-Q11-R11-S11-T11-U11-V11-W11-X11-Y11 -> 6300000 | AB11: TT/01026/06/V | AC11: Tmpt Parkir | AD11: LDC.HK.0913.0002
A12: 3 | B12: 1 | C12: 2012 | D12: 9.0000007 | G12: Nissan | H12: 8 | I12: =+H12*12 -> 96 | J12: 136882273 | K12: =J12/I12 -> 1425857 | L12: 5703428 | M12: =J12-L12 -> 1.3117884e+08 | N12: =$K$12 -> 1425857 | O12: =$K$12 -> 1425857 | P12: =$K$12 -> 1425857 | Q12: =$K$12 -> 1425857 | R12: =$K$12 -> 1425857 | S12: =$K$12 -> 1425857 | T12: =$K$12 -> 1425857 | U12: =$K$12 -> 1425857 | ... Y12: =$K$12 -> 1425857 | Z12: =L12+N12+O12+P12+Q12+R12+S12+T12+U12+V12+W12+X12+Y12 -> 22813712 | AA12: =M12-N12-O12-P12-Q12-R12-S12-T12-U12-V12-W12-X12-Y12 -> 1.1406856e+08 | AB12: TT/04019/07/V | AC12: Mutasi | AD12: BLD.FB.1014.0003 | AF12: GTH1 | AG12: BLD | AH12: . | AI12: FB | AJ12: . | AK12: 1014 | AL12: . | AM12: 0003 | AN12: =CONCATENATE(AG12,AH12,AI12,AJ12,AK12,AL12,AM12) -> BLD.FB.1014.0003
A13: 4 | B13: 1 | C13: 2012 | D13: 9.0000007 | G13: Nissan | H13: 8 | I13: =+H13*12 -> 96 | J13: 234060909 | K13: =J13/I13 -> 2438134.5 | L13: 9752537.9 | M13: =J13-L13 -> 2.2430837e+08 | N13: =$K$13 -> 2438134.5 | O13: =$K$13 -> 2438134.5 | P13: =$K$13 -> 2438134.5 | Q13: =$K$13 -> 2438134.5 | R13: =$K$13 -> 2438134.5 | S13: =$K$13 -> 2438134.5 | T13: =$K$13 -> 2438134.5 | U13: =$K$13 -> 2438134.5 | ... Y13: =$K$13 -> 2438134.5 | Z13: =L13+N13+O13+P13+Q13+R13+S13+T13+U13+V13+W13+X13+Y13 -> 39010152 | AA13: =M13-N13-O13-P13-Q13-R13-S13-T13-U13-V13-W13-X13-Y13 -> 1.9505076e+08 | AB13: TT/06030/07/V | AC13: Jual ke PHK 3 | AD13: MCH.KC.0914.0004 | AF13: WHY1 | AG13: MCH | AH13: . | AI13: KC | AJ13: . | AK13: 0914 | AL13: . | AM13: 0004 | AN13: =CONCATENATE(AG13,AH13,AI13,AJ13,AK13,AL13,AM13) -> MCH.KC.0914.0004
A14: 5 | B14: 1 | C14: 2012 | D14: 9.0000007 | G14: Nissan | H14: 8 | I14: =+H14*12 -> 96 | J14: 130553182 | K14: =J14/I14 -> 1359929 | L14: 5439715.9 | M14: =J14-L14 -> 1.2511347e+08 | N14: =$K$14 -> 1359929 | O14: =$K$14 -> 1359929 | P14: =$K$14 -> 1359929 | Q14: =$K$14 -> 1359929 | R14: =$K$14 -> 1359929 | S14: =$K$14 -> 1359929 | T14: =$K$14 -> 1359929 | U14: =$K$14 -> 1359929 | ... Y14: =$K$14 -> 1359929 | Z14: =L14+N14+O14+P14+Q14+R14+S14+T14+U14+V14+W14+X14+Y14 -> 21758864 | AA14: =M14-N14-O14-P14-Q14-R14-S14-T14-U14-V14-W14-X14-Y14 -> 1.0879432e+08 | AB14: TT/12029/07/V | AC14: Jual ke PHK 3 | AD14: GBS.SP.1015.0005 | AF14: WHS1 | AG14: GBS | AH14: . | AI14: SP | AJ14: . | AK14: 1015 | AL14: . | AM14: 0005 | AN14: =CONCATENATE(AG14,AH14,AI14,AJ14,AK14,AL14,AM14) -> GBS.SP.1015.0005
A15: 6 | B15: 1 | C15: 2012 | D15: 9.0000007 | G15: Suzuki | H15: 4 | I15: =+H15*12 -> 48 | J15: 9824091 | K15: =J15/I15 -> 204668.56 | L15: 818674.25 | M15: =J15-L15 -> 9005416.8 | N15: =$K$15 -> 204668.56 | O15: =$K$15 -> 204668.56 | P15: =$K$15 -> 204668.56 | Q15: =$K$15 -> 204668.56 | R15: =$K$15 -> 204668.56 | S15: =$K$15 -> 204668.56 | T15: =$K$15 -> 204668.56 | U15: =$K$15 -> 204668.56 | ... Y15: =$K$15 -> 204668.56 | Z15: =L15+N15+O15+P15+Q15+R15+S15+T15+U15+V15+W15+X15+Y15 -> 3274697 | AA15: =M15-N15-O15-P15-Q15-R15-S15-T15-U15-V15-W15-X15-Y15 -> 6549394 | AB15: TT/04034/08/V | AC15: Tmpt Parkir | AD15: FNF.OO.0915.0006 | AF15: WHC1 | AG15: FNF | AH15: . | AI15: OO | AJ15: . | AK15: 0915 | AL15: . | AM15: 0006 | AN15: =CONCATENATE(AG15,AH15,AI15,AJ15,AK15,AL15,AM15) -> FNF.OO.0915.0006
A16: 7 | B16: 1 | C16: 2012 | D16: 9.0000007 | G16: X-Trail | H16: 4 | I16: =+H16*12 -> 48 | J16: 251793182 | K16: =J16/I16 -> 5245691.3 | L16: 20982765 | M16: =J16-L16 -> 2.3081042e+08 | N16: =$K$16 -> 5245691.3 | O16: =$K$16 -> 5245691.3 | P16: =$K$16 -> 5245691.3 | Q16: =$K$16 -> 5245691.3 | R16: =$K$16 -> 5245691.3 | S16: =$K$16 -> 5245691.3 | T16: =$K$16 -> 5245691.3 | U16: =$K$16 -> 5245691.3 | ... Y16: =$K$16 -> 5245691.3 | Z16: =L16+N16+O16+P16+Q16+R16+S16+T16+U16+V16+W16+X16+Y16 -> 83931061 | AA16: =M16-N16-O16-P16-Q16-R16-S16-T16-U16-V16-W16-X16-Y16 -> 1.6786212e+08 | AB16: TT/07019/08/V | AC16: Tmpt Parkir | AD16: OEQ.EN.1016.0007 | AF16: WPCC | AG16: OEQ | AH16: . | AI16: EN | AJ16: . | AK16: 1016 | AL16: . | AM16: 0007 | AN16: =CONCATENATE(AG16,AH16,AI16,AJ16,AK16,AL16,AM16) -> OEQ.EN.1016.0007
A17: 8 | B17: 1 | C17: 2012 | D17: 9.0000007 | G17: Nissan | H17: 8 | I17: =+H17*12 -> 96 | J17: 165424092 | K17: =J17/I17 -> 1723167.6 | L17: 6892670.5 | M17: =J17-L17 -> 1.5853142e+08 | N17: =$K$17 -> 1723167.6 | O17: =$K$17 -> 1723167.6 | P17: =$K$17 -> 1723167.6 | Q17: =$K$17 -> 1723167.6 | R17: =$K$17 -> 1723167.6 | S17: =$K$17 -> 1723167.6 | T17: =$K$17 -> 1723167.6 | U17: =$K$17 -> 1723167.6 | ... Y17: =$K$17 -> 1723167.6 | Z17: =L17+N17+O17+P17+Q17+R17+S17+T17+U17+V17+W17+X17+Y17 -> 27570682 | AA17: =M17-N17-O17-P17-Q17-R17-S17-T17-U17-V17-W17-X17-Y17 -> 137853410 | AB17: IV/11012/09/V | AC17: Tmpt Parkir | AD17: VHC.SM.0916.0008 | AF17: WPKG | AG17: VHC | AH17: . | AI17: SM | AJ17: . | AK17: 0916 | AL17: . | AM17: 0008 | AN17: =CONCATENATE(AG17,AH17,AI17,AJ17,AK17,AL17,AM17) -> VHC.SM.0916.0008
A18: 9 | B18: 1 | C18: 2012 | D18: 9.0000007 | G18: Serena | H18: 8 | I18: =+H18*12 -> 96 | J18: 244950455 | K18: =J18/I18 -> 2551567.2 | L18: 10206269 | M18: =J18-L18 -> 2.3474419e+08 | N18: =$K$18 -> 2551567.2 | O18: =$K$18 -> 2551567.2 | P18: =$K$18 -> 2551567.2 | Q18: =$K$18 -> 2551567.2 | R18: =$K$18 -> 2551567.2 | S18: =$K$18 -> 2551567.2 | T18: =$K$18 -> 2551567.2 | U18: =$K$18 -> 2551567.2 | ... Y18: =$K$18 -> 2551567.2 | Z18: =L18+N18+O18+P18+Q18+R18+S18+T18+U18+V18+W18+X18+Y18 -> 40825076 | AA18: =M18-N18-O18-P18-Q18-R18-S18-T18-U18-V18-W18-X18-Y18 -> 2.0412538e+08 | AB18: IV/11012/09/V | AC18: Tmpt Parkir | AD18: SWR.AG.1017.0009 | AF18: GWKG | AG18: SWR | AH18: . | AI18: AG | AJ18: . | AK18: 1017 | AL18: . | AM18: 0009 | AN18: =CONCATENATE(AG18,AH18,AI18,AJ18,AK18,AL18,AM18) -> SWR.AG.1017.0009
A19: 10 | B19: 1 | C19: 2012 | D19: 9.0000007 | G19: Livina | H19: 8 | I19: =+H19*12 -> 96 | J19: 144592273 | K19: =J19/I19 -> 1506169.5 | L19: 6024678 | M19: =J19-L19 -> 1.3856759e+08 | N19: =$K$19 -> 1506169.5 | O19: =$K$19 -> 1506169.5 | P19: =$K$19 -> 1506169.5 | Q19: =$K$19 -> 1506169.5 | R19: =$K$19 -> 1506169.5 | S19: =$K$19 -> 1506169.5 | T19: =$K$19 -> 1506169.5 | U19: =$K$19 -> 1506169.5 | ... Y19: =$K$19 -> 1506169.5 | Z19: =L19+N19+O19+P19+Q19+R19+S19+T19+U19+V19+W19+X19+Y19 -> 24098712 | AA19: =M19-N19-O19-P19-Q19-R19-S19-T19-U19-V19-W19-X19-Y19 -> 1.2049356e+08 | AB19: IV/09018/10/V | AC19: Tmpt Parkir | AD19: GWL.EN.1014.0010 | AF19: GWND | AG19: GWL | AH19: . | AI19: EN | AJ19: . | AK19: 1014 | AL19: . | AM19: 0010 | AN19: =CONCATENATE(AG19,AH19,AI19,AJ19,AK19,AL19,AM19) -> GWL.EN.1014.0010
A20: 11 | B20: 1 | C20: 2012 | D20: 9.0000007 | G20: March | H20: 8 | I20: =+H20*12 -> 96 | J20: 131402727 | K20: =J20/I20 -> 1368778.4 | L20: 5475113.6 | M20: =J20-L20 -> 1.2592761e+08 | N20: =$K$20 -> 1368778.4 | O20: =$K$20 -> 1368778.4 | P20: =$K$20 -> 1368778.4 | Q20: =$K$20 -> 1368778.4 | R20: =$K$20 -> 1368778.4 | S20: =$K$20 -> 1368778.4 | T20: =$K$20 -> 1368778.4 | U20: =$K$20 -> 1368778.4 | ... Y20: =$K$20 -> 1368778.4 | Z20: =L20+N20+O20+P20+Q20+R20+S20+T20+U20+V20+W20+X20+Y20 -> 21900454 | AA20: =M20-N20-O20-P20-Q20-R20-S20-T20-U20-V20-W20-X20-Y20 -> 1.0950227e+08 | AB20: TT/12015/10/V | AC20: Tmpt Parkir | AD20: LCS.SM.0914.0011 | AG20: LCS | AH20: . | AI20: SM | AJ20: . | AK20: 0914 | AL20: . | AM20: 0011 | AN20: =CONCATENATE(AG20,AH20,AI20,AJ20,AK20,AL20,AM20) -> LCS.SM.0914.0011
A22: =CONCATENATE("TOTAL ",$B$7) -> TOTAL | J22: =SUM(J10:J21) -> 1665767048 | K22: =SUM(K10:K21) -> 20175358 | L22: =SUM(L10:L21) -> 80701430 | M22: =SUM(M10:M21) -> 1.5850656e+09 | N22: =SUM(N10:N21) -> 20175358 | O22: =SUM(O10:O21) -> 20175358 | P22: =SUM(P10:P21) -> 20175358 | Q22: =SUM(Q10:Q21) -> 20175358 | ... Y22: =SUM(Y10:Y21) -> 20175358 | Z22: =SUM(Z10:Z20) -> 3.2280572e+08 | AA22: =SUM(AA10:AA21) -> 1.3429613e+09
AF26: Building | AG26: BLD
AF27: Machine | AG27: MCH
AF28: General Building System Equipment | AG28: GBS
AF29: Furniture & Fixture | AG29: FNF
AF30: Other Equipment | AG30: OEQ
AF31: Vehicle | AG31: VHC
AF32: Software | AG32: SWR
AF33: Goodwill | AG33: GWL
AF34: License | AG34: LCS
AF35: Building Rights on Land | AG35: BRL
AF36: Other Intangible Asset | AG36: OIA
AF37: Non Capitalized Asset | AG37: NCA
... AF46: Administrative & General | AG46: AG

Sheet CF WS
A1: PT. Estrella Delapan Indonesia
A2: Statement of Cash Flow
A3: For the month ended
B5: Descriptions | C5: YTD | D5: Janruari | E5: Februari | F5: Maret | G5: April | H5: Mei | I5: Juni | J5: Juli | K5: Agustus | L5: September | M5: Oktober | N5: November | O5: Desember
C6: Actual | D6: Actual | E6: Actual | F6: Actual | G6: Actual | H6: Actual | I6: Actual | J6: Actual | K6: Actual | L6: Actual | M6: Actual | N6: Actual | O6: Actual
A8: 1. Cash Flows from Operating Activities | C8: =SUM(C9:C14) -> 0 | D8: =SUM(D9:D14) -> 0 | E8: =SUM(E9:E14) -> 0 | F8: =SUM(F9:F14) -> 0 | G8: =SUM(G9:G14) -> 0 | H8: =SUM(H9:H14) -> 0 | I8: =SUM(I9:I14) -> 0 | J8: =SUM(J9:J14) -> 0 | ... O8: =SUM(O9:O14) -> 0
B9: Guest Receipts | C9: =SUM(D9:O9) -> 0
B10: Other Receipts | C10: =SUM(D10:O10) -> 0
B11: Payroll Disbursements | C11: =SUM(D11:O11) -> 0
B12: Operating Disbursements | C12: =SUM(D12:O12) -> 0
B13: Taxes Paid | C13: =SUM(D13:O13) -> 0
B14: Management Fees Paid | C14: =SUM(D14:O14) -> 0
A16: 2. Cash Flows from Investing Activities | C16: =SUM(C17:C35) -> 0 | D16: =SUM(D17:D35) -> 0 | E16: =SUM(E17:E35) -> 0 | F16: =SUM(F17:F35) -> 0 | G16: =SUM(G17:G35) -> 0 | H16: =SUM(H17:H35) -> 0 | I16: =SUM(I17:I35) -> 0 | J16: =SUM(J17:J35) -> 0 | ... O16: =SUM(O17:O35) -> 0
B17: Capital Expenditures
B18: Land | C18: =SUM(D18:O18) -> 0
B19: Building | C19: =SUM(D19:O19) -> 0
B20: Equipment | C20: =SUM(D20:O20) -> 0
B21: Vehicle | C21: =SUM(D21:O21) -> 0
B22: Intangible Asset | C22: =SUM(D22:O22) -> 0
B23: Operating Asset | C23: =SUM(D23:O23) -> 0
B25: Proceeds from Sale of Fixed Asset
B26: Land | C26: =SUM(D26:O26) -> 0
B27: Building | C27: =SUM(D27:O27) -> 0
B28: Equipment | C28: =SUM(D28:O28) -> 0
B29: Vehicle | C29: =SUM(D29:O29) -> 0
B30: Intangible Asset | C30: =SUM(D30:O30) -> 0
B31: Operating Asset | C31: =SUM(D31:O31) -> 0
B33: Proceeds from Interest Income and Time Deposit | C33: =SUM(D33:O33) -> 0
A36: 3. Cash Flows from Financing Activities | C36: =SUM(C37:C41) -> 0 | D36: =SUM(D37:D41) -> 0 | E36: =SUM(E37:E41) -> 0 | F36: =SUM(F37:F41) -> 0 | G36: =SUM(G37:G41) -> 0 | H36: =SUM(H37:H41) -> 0 | I36: =SUM(I37:I41) -> 0 | J36: =SUM(J37:J41) -> 0 | ... O36: =SUM(O37:O41) -> 0
B37: Proceeds from Debt or Equity Financing | C37: =SUM(D37:O37) -> 0
B38: Debt Repayments | C38: =SUM(D38:O38) -> 0
B39: Dividends Paid | C39: =SUM(D39:O39) -> 0
B40: Distribution to Owners | C40: =SUM(D40:O40) -> 0
A42: Net Increase (Decrease) in Cash and Cash Equivalents | C42: =C8+C16+C36 -> 0 | D42: =D8+D16+D36 -> 0 | E42: =E8+E16+E36 -> 0 | F42: =F8+F16+F36 -> 0 | G42: =G8+G16+G36 -> 0 | H42: =H8+H16+H36 -> 0 | I42: =I8+I16+I36 -> 0 | J42: =J8+J16+J36 -> 0 | ... O42: =O8+O16+O36 -> 0
A44: Cash and Cash Equivalents, Beginning of Period | C44: =D44 -> 0 | E44: =IF(E42=0,0,D46) -> 0 | F44: =IF(F42=0,0,E46) -> 0 | G44: =IF(G42=0,0,F46) -> 0 | H44: =IF(H42=0,0,G46) -> 0 | I44: =IF(I42=0,0,H46) -> 0 | J44: =IF(J42=0,0,I46) -> 0 | K44: =IF(K42=0,0,J46) -> 0 | L44: =IF(L42=0,0,K46) -> 0 | ... O44: =IF(O42=0,0,N46) -> 0
A46: Cash and Cash Equivalents, End of Period | C46: =C44+C42 -> 0 | D46: =D44+D42 -> 0 | E46: =E44+E42 -> 0 | F46: =F44+F42 -> 0 | G46: =G44+G42 -> 0 | H46: =H44+H42 -> 0 | I46: =I44+I42 -> 0 | J46: =J44+J42 -> 0 | ... O46: =O44+O42 -> 0
A48: Cash and Cash Equivalents, End of Period - GL | E48: =[1]KONV!C204 -> 0 | F48: =[1]KONV!D204 -> 0 | G48: =[1]KONV!E204 -> 0 | H48: =[1]KONV!F204 -> 0 | I48: =[1]KONV!G204 -> 0 | J48: =[1]KONV!H204 -> 0 | K48: =[1]KONV!I204 -> 0 | L48: =[1]KONV!J204 -> 0 | ... O48: =[1]KONV!M204 -> 0

Sheet AR
A1: PT. Estrella Delapan Indonesia
A2: Accounts Receivable Aging
A3: For the month ended March 2016
A5: No | B5: Customer | C5: Balance | D5: Mutation | F5: Balance | G5: Accounts Receivable Aging
C6: Beginning | D6: Sales | E6: Payment | F6: Ending | G6: 0 - 15 | H6: 16 - 30 | I6: 31 - 60 | J6: 61 - 90 | K6: > 90
A7: 1 | B7: Credit Card Visa Mandiri | C7: 0 | D7: 1352400 | E7: 0 | F7: =C7+D7-E7 -> 1352400 | H7: =F7 -> 1352400
A8: 2 | B8: Credit Card Master Mandiri | C8: 0 | D8: 676200 | E8: 0 | F8: =C8+D8-E8 -> 676200 | H8: =F8 -> 676200
A9: 3 | B9: Debit Bank Mandiri | C9: 0 | D9: 688275 | E9: -53137.05 | F9: 635137.95 | H9: 688275
A10: 4 | B10: BRI Kanwil Makassar | C10: 0 | D10: 1014300 | E10: 0 | F10: =C10+D10-E10 -> 1014300 | G10: =F10 -> 1014300
A11: 5 | B11: Traveloka | C11: 0 | D11: 835763 | E11: 0 | F11: =C11+D11-E11 -> 835763 | G11: =F11 -> 835763
A12: 6 | B12: Agoda | C12: 0 | D12: 35462082 | E12: 0 | F12: =C12+D12-E12 -> 35462082 | G12: 35462082 | H12: 0
A13: 7 | B13: Expedia | C13: 0 | D13: 609221 | F13: =C13+D13-E13 -> 609221 | G13: =F13 -> 609221 | H13: 0
A14: 8 | B14: MG Holiday | C14: 0 | D14: 1200000 | F14: =C14+D14-E14 -> 1200000 | G14: 600000 | H14: 600000
A15: 9 | B15: Antavaya | C15: 0 | D15: 900000 | F15: =C15+D15-E15 -> 900000 | G15: =F15 -> 900000
B16: Hokky Mandiri Travel | C16: 0 | D16: 975000 | F16: =C16+D16-E16 -> 975000 | G16: =F16 -> 975000
C17: 0 | F17: =C17+D17-E17 -> 0 | G17: =F17 -> 0
C18: 0 | F18: =C18+D18-E18 -> 0 | G18: =F18 -> 0
C19: 0 | F19: =C19+D19-E19 -> 0 | G19: =F19 -> 0
C20: 0 | F20: =C20+D20-E20 -> 0 | G20: =F20 -> 0
C21: 0 | F21: =C21+D21-E21 -> 0 | G21: =F21 -> 0
C22: 0 | F22: =C22+D22-E22 -> 0 | G22: =F22 -> 0
C23: 0 | F23: =C23+D23-E23 -> 0 | G23: =F23 -> 0
B25: Total | C25: =SUM(C7:C24) -> 0 | D25: =SUM(D7:D24) -> 43713241 | E25: =SUM(E7:E24) -> -53137.05 | F25: =SUM(F7:F24) -> 43660104 | G25: =SUM(G7:G24) -> 40396366 | H25: =SUM(H7:H24) -> 3316875 | I25: =SUM(I7:I24) -> 0 | J25: =SUM(J7:J24) -> 0 | K25: =SUM(K7:K24) -> 0
B26: Average Days Credit Sales Outstanding (DCSO) : | C26: 0.0562 | D26: 1 | E26: =E25/D25 -> -0.0012155825 | G26: =G25/F25 -> 0.92524667 | H26: =H25/F25 -> 0.075970387

Sheet AP
A1: PT. Estrella Delapan Indonesia
A2: Accounts Payable Aging
A3: For the month ended April 2016
A5: No | B5: Supplier | C5: Balance | D5: Mutation | F5: Balance | G5: Accounts Payable Aging
C6: Beginning | D6: Payment | E6: Purchases | F6: Ending | G6: 0 - 15 | H6: 16 - 30 | I6: 31 - 60 | J6: 61 - 90 | K6: > 90
A8: 1 | B8: Aneka Jaya | C8: 11541302 | E8: 5922072 | F8: =C8-D8+E8 -> 17463374 | H8: 11541302
A9: 2 | B9: CV.Bintang Mas | C9: 3614000 | D9: 2764550 | E9: 3614000 | F9: =C9-D9+E9 -> 4463450 | H9: 849450
A10: 3 | B10: CV.Utama Mandiri | C10: 4930000 | E10: 5355000 | F10: =C10-D10+E10 -> 10285000
A11: 4 | B11: Aura Catering | C11: 7176000 | D11: 7176000 | E11: 0 | F11: =C11-D11+E11 -> 0
A12: 5 | B12: Aroma Coto Gagak | C12: 22260000 | D12: 22260000 | E12: 0 | F12: =C12-D12+E12 -> 0
A13: 6 | B13: PT.Reborn Cleaning Service | C13: 65879016 | D13: 65879016 | E13: 0 | F13: =C13-D13+E13 -> 0
A14: 7 | B14: CV.Sari Bumi Kencana | C14: 3012000 | D14: 3012000 | E14: 1506000 | F14: =C14-D14+E14 -> 1506000
A15: 8 | B15: KR. Cathering | C15: 37770000 | D15: 37700000 | F15: =C15-D15+E15 -> 70000
A16: 9 | B16: PT.Indocare Pacific | C16: 16148000 | D16: 16148000 | E16: 8074000 | F16: =C16-D16+E16 -> 8074000
A17: 10 | B17: Arifah Laundry | C17: 20464250 | D17: 20464250 | F17: =C17-D17+E17 -> 0
A18: 11 | B18: MG Transport | C18: 4275000 | D18: 4275000 | F18: =C18-D18+E18 -> 0
A19: 12 | B19: Malikah Catering Service | C19: 34060000 | D19: 34060000 | F19: =C19-D19+E19 -> 0
A20: 13 | B20: Muslim Aisyah Catering | C20: 12336000 | D20: 12336000 | F20: =C20-D20+E20 -> 0
A21: 14 | B21: Toko Osaka | C21: 8936700 | D21: 8936700 | F21: =C21-D21+E21 -> 0
A22: 15 | B22: Roxy Advertising | C22: 5425000 | D22: 5425000 | E22: 12570000 | F22: =C22-D22+E22 -> 12570000
A23: 16 | B23: CV.Santri Karya Mandiri | C23: 3906000 | D23: 2098000 | E23: 9014000 | F23: =C23-D23+E23 -> 10822000
A24: 17 | B24: Tirta Makmur Perkasa | C24: 4590000 | E24: 7362500 | F24: =C24-D24+E24 -> 11952500
A25: 18 | B25: Cash Purchase | E25: 240300 | F25: =C25-D25+E25 -> 240300
A26: 19 | B26: CV.Surya Perkasa | E26: 3891415 | F26: =C26-D26+E26 -> 3891415
A27: 20 | B27: Toko Sumber listrik | E27: =487500+150000 -> 637500 | F27: =C27-D27+E27 -> 637500
A28: 21 | B28: Lumbung Bangunan | E28: 415000 | F28: =C28-D28+E28 -> 415000
A29: 22 | E29: 11275000 | F29: =C29-D29+E29 -> 11275000
A30: 23 | E30: 560000 | F30: =C30-D30+E30 -> 560000
A31: 24 | E31: 189000 | F31: =C31-D31+E31 -> 189000
A32: 25 | E32: 90180000 | F32: =C32-D32+E32 -> 90180000
A33: 26 | E33: 3000000 | F33: =C33-D33+E33 -> 3000000
A34: 27 | E34: 2800000 | F34: =C34-D34+E34 -> 2800000
A35: 28 | E35: 8074000 | F35: =C35-D35+E35 -> 8074000
A36: 29 | E36: 1050000 | F36: =C36-D36+E36 -> 1050000
A37: 30 | E37: 2405000 | F37: =C37-D37+E37 -> 2405000
A38: 31 | E38: 2115000 | F38: =C38-D38+E38 -> 2115000
A39: 32 | E39: 11790000 | F39: =C39-D39+E39 -> 11790000
A40: 33 | E40: 3200000 | F40: =C40-D40+E40 -> 3200000
... A42: 35 | E42: 1125000 | F42: =C42-D42+E42 -> 1125000
A43: 36
...

Sheet PL Summary
B5: Description | C5: Years | D5: month | E5: % | F5: Daily | G5: %
B7: Number of Day | C7: 365 | D7: 30 | F7: 1
B8: Room Available | C8: =37*C7 -> 13505 | D8: =78*D7 -> 2340 | F8: =78*F7 -> 78
B9: Room Paid | C9: =C10*C8 -> 8586.9292 | D9: =D10*D8 -> 1404 | F9: =F10*F8 -> 46.8
B10: Occupancy % | C10: ='[2]1 Year Consolidated'!$Z$10 -> 0.63583333 | D10: 0.6 | F10: 0.6
B11: ARR | C11: =[2]INTRODUCTION!$H$44 -> 83220.29 | D11: =C11 -> 83220.29 | F11: =C11 -> 83220.29
B12: Revpar | C12: =C16/C8 -> 52914.235 | D12: =C12 -> 52914.235 | F12: =D12 -> 52914.235
B13: Complimentary | C13: 0 | F13: =C13-D13 -> 0
B15: Revenue
B16: Room | C16: =C11*C9 -> 7.1460674e+08 | D16: =C16/12 -> 59550561 | E16: =D16/$D$21 -> 1 | F16: =F11*F9 -> 3894709.6 | G16: =F16/$D$21 -> 0.065401727
B17: Food & Beverage | C17: =#REF! -> #REF! | E17: =D17/$D$21 -> 0 | G17: =F17/$D$21 -> 0
B18: Banquet & Meeting Package | E18: =D18/$D$21 -> 0 | G18: =F18/$D$21 -> 0
B19: Other Operating | E19: =D19/$D$21 -> 0 | G19: =F19/$D$21 -> 0
B21: TOTAL REVENUE | C21: =SUM(C16:C19) -> #REF! | D21: =SUM(D16:D19) -> 59550561 | E21: =SUM(E16:E19) -> 1 | F21: =SUM(F16:F19) -> 3894709.6 | G21: =SUM(G16:G19) -> 0.065401727
B23: Direct Expenses
B25: Cost of Sales | C25: =SUM(C26:C29) -> 0 | D25: =SUM(D26:D29) -> 0 | E25: =D25/$D$21 -> 0 | F25: =SUM(F26:F29) -> 0 | G25: =F25/D25 -> #DIV/0!
B26: Food & Beverage | E26: =D26/$D$21 -> 0 | F26: =C26-D26 -> 0 | G26: =F26/D26 -> #DIV/0!
B27: Banquet & Meeting Package | E27: =D27/$D$21 -> 0 | F27: =C27-D27 -> 0 | G27: =F27/D27 -> #DIV/0!
B28: Spa | E28: =D28/$D$21 -> 0 | F28: =C28-D28 -> 0 | G28: =F28/D28 -> #DIV/0!
B29: Other Operating | E29: =D29/$D$21 -> 0 | F29: =C29-D29 -> 0 | G29: =F29/D29 -> #DIV/0!
B31: Payroll and Related Expenses | C31: =SUM(C32:C37) -> 0 | D31: =SUM(D32:D37) -> 0 | E31: =D31/$D$21 -> 0 | F31: =SUM(F32:F37) -> 0 | G31: =F31/D31 -> #DIV/0!
B32: Room | E32: =D32/$D$21 -> 0 | F32: =C32-D32 -> 0 | G32: =F32/D32 -> #DIV/0!
B33: Housekeeping | E33: =D33/$D$21 -> 0 | F33: =C33-D33 -> 0 | G33: =F33/D33 -> #DIV/0!
B34: Food & Beverage | E34: =D34/$D$21 -> 0 | F34: =C34-D34 -> 0 | G34: =F34/D34 -> #DIV/0!
B35: Kitchen | E35: =D35/$D$21 -> 0 | F35: =C35-D35 -> 0 | G35: =F35/D35 -> #DIV/0!
B36: Spa | E36: =D36/$D$21 -> 0 | F36: =C36-D36 -> 0 | G36: =F36/D36 -> #DIV/0!
B37: Other Operating | E37: =D37/$D$21 -> 0 | F37: =C37-D37 -> 0 | G37: =F37/D37 -> #DIV/0!
B39: Operating Expenses | C39: =SUM(C40:C43) -> 0 | D39: =SUM(D40:D43) -> 0 | E39: =D39/$D$21 -> 0 | F39: =SUM(F40:F43) -> 0 | G39: =F39/D39 -> #DIV/0!
B40: Room | E40: =D40/$D$21 -> 0 | F40: =C40-D40 -> 0 | G40: =F40/D40 -> #DIV/0!
B41: Food & Beverage | E41: =D41/$D$21 -> 0 | F41: =C41-D41 -> 0 | G41: =F41/D41 -> #DIV/0!
B42: Spa | E42: =D42/$D$21 -> 0 | F42: =C42-D42 -> 0 | G42: =F42/D42 -> #DIV/0!
B43: Other Operating | E43: =D43/$D$21 -> 0 | F43: =C43-D43 -> 0 | G43: =F43/D43 -> #DIV/0!
B45: Provision for Replacement | C45: =SUM(C46:C49) -> 0 | D45: =SUM(D46:D49) -> 0 | E45: =D45/$D$21 -> 0 | F45: =SUM(F46:F49) -> 0 | G45: =F45/D45 -> #DIV/0!
B46: Room | E46: =D46/$D$21 -> 0 | F46: =C46-D46 -> 0 | G46: =F46/D46 -> #DIV/0!
B47: Food & Beverage | E47: =D47/$D$21 -> 0 | F47: =C47-D47 -> 0 | G47: =F47/D47 -> #DIV/0!
B48: Spa | E48: =D48/$D$21 -> 0 | F48: =C48-D48 -> 0 | G48: =F48/D48 -> #DIV/0!
B49: Other Operating | E49: =D49/$D$21 -> 0 | F49: =C49-D49 -> 0 | G49: =F49/D49 -> #DIV/0!
B51: TOTAL DIRECT EXPENSES | C51: =C25+C31+C39+C45 -> 0 | D51: =D25+D31+D39+D45 -> 0 | E51: =D51/$D$21 -> 0 | F51: =C51-D51 -> 0 | G51: =F51/D51 -> #DIV/0!
B53: Undistributed Expenses
B55: Payroll and Related Expenses | C55: =SUM(C56:C58) -> 0 | D55: =SUM(D56:D58) -> 0 | E55: =D55/$D$21 -> 0 | F55: =SUM(F56:F58) -> 0 | G55: =F55/D55 -> #DIV/0!
...

Sheet PL Detail
B1: PT.
B2: Income Statement Detail
B3: For the month ended
D4: THIS MONTH | J4: YEAR TO DATE | P4: LAST YEAR SAME MONTH
B5: Description | D5: Actual | E5: % | F5: Budget | G5: % | H5: Variance | I5: % | J5: Actual | K5: % | L5: Budget | M5: % | N5: Variance | O5: % | P5: Current Period | Q5: Variance | R5: Year To Date | S5: Variance
B7: No of Days | D7: =#REF! -> #REF! | F7: ='PL Summary'!D7 -> 30 | H7: ='PL Summary'!F7 -> 1 | J7: ='PL Summary'!#REF! -> #REF! | L7: ='PL Summary'!#REF! -> #REF! | N7: ='PL Summary'!#REF! -> #REF!
B8: No of Room Build | D8: =#REF! -> #REF! | F8: ='PL Summary'!#REF! -> #REF! | H8: ='PL Summary'!#REF! -> #REF! | J8: ='PL Summary'!#REF! -> #REF! | L8: ='PL Summary'!#REF! -> #REF! | N8: ='PL Summary'!#REF! -> #REF!
B9: Total Room Build | D9: =#REF! -> #REF! | F9: ='PL Summary'!D8 -> 2340 | H9: ='PL Summary'!F8 -> 78 | J9: ='PL Summary'!#REF! -> #REF! | L9: ='PL Summary'!#REF! -> #REF! | N9: ='PL Summary'!#REF! -> #REF!
B10: Out of Inventory | D10: =#REF! -> #REF! | F10: ='PL Summary'!#REF! -> #REF! | H10: ='PL Summary'!#REF! -> #REF! | J10: ='PL Summary'!#REF! -> #REF! | L10: ='PL Summary'!#REF! -> #REF! | N10: ='PL Summary'!#REF! -> #REF!
B11: House Use | D11: =#REF! -> #REF! | F11: ='PL Summary'!D9 -> 1404 | H11: ='PL Summary'!F9 -> 46.8 | J11: ='PL Summary'!#REF! -> #REF! | L11: ='PL Summary'!#REF! -> #REF! | N11: ='PL Summary'!#REF! -> #REF!
B12: Total Room Available | D12: =#REF! -> #REF! | F12: ='PL Summary'!D10 -> 0.6 | H12: ='PL Summary'!F10 -> 0.6 | J12: ='PL Summary'!#REF! -> #REF! | L12: ='PL Summary'!#REF! -> #REF! | N12: ='PL Summary'!#REF! -> #REF!
B13: Out of Order | D13: =#REF! -> #REF! | F13: ='PL Summary'!D11 -> 83220.29 | H13: ='PL Summary'!F11 -> 83220.29 | J13: ='PL Summary'!#REF! -> #REF! | L13: ='PL Summary'!#REF! -> #REF! | N13: ='PL Summary'!#REF! -> #REF!
B14: Total Room Saleable | D14: =#REF! -> #REF! | F14: ='PL Summary'!D12 -> 52914.235 | H14: ='PL Summary'!F12 -> 52914.235 | J14: ='PL Summary'!#REF! -> #REF! | L14: ='PL Summary'!#REF! -> #REF! | N14: ='PL Summary'!#REF! -> #REF!
B15: Complimentary | D15: =#REF! -> #REF! | F15: ='PL Summary'!D13 -> 0 | H15: ='PL Summary'!F13 -> 0 | J15: ='PL Summary'!#REF! -> #REF! | L15: ='PL Summary'!#REF! -> #REF! | N15: ='PL Summary'!#REF! -> #REF!
B16: Room Paid | D16: =#REF! -> #REF! | E16: =D16/F16 -> #REF! | F16: ='PL Summary'!#REF! -> #REF! | H16: ='PL Summary'!#REF! -> #REF! | I16: =H16/F16 -> #REF! | J16: ='PL Summary'!#REF! -> #REF! | K16: =J16/L16 -> #REF! | L16: ='PL Summary'!#REF! -> #REF! | N16: ='PL Summary'!#REF! -> #REF! | O16: =N16/L16 -> #REF! | Q16: =(D16-P16)/P16 -> #REF! | S16: =(J16-R16)/R16 -> #REF!
B17: Occupancy % | D17: =#REF! -> #REF! | F17: ='PL Summary'!#REF! -> #REF! | H17: ='PL Summary'!#REF! -> #REF! | J17: ='PL Summary'!#REF! -> #REF! | L17: ='PL Summary'!#REF! -> #REF! | N17: ='PL Summary'!#REF! -> #REF! | P17: =(P15+P16)/P9 -> #DIV/0! | Q17: =(D17-P17)/P17 -> #REF! | R17: =(R15+R16)/R9 -> #DIV/0! | S17: =(J17-R17)/R17 -> #REF!
B18: ARR | D18: =#REF! -> #REF! | E18: =D18/F18 -> #REF! | F18: ='PL Summary'!#REF! -> #REF! | G18: 1 | H18: ='PL Summary'!#REF! -> #REF! | I18: =H18/F18 -> #REF! | J18: ='PL Summary'!#REF! -> #REF! | K18: =J18/L18 -> #REF! | L18: ='PL Summary'!#REF! -> #REF! | M18: 1 | N18: ='PL Summary'!#REF! -> #REF! | O18: =N18/L18 -> #REF! | P18: =#REF!/(P16+P15) -> #REF! | Q18: =(D18-P18)/P18 -> #REF! | R18: =#REF!/(R16+R15) -> #REF! | S18: =(J18-R18)/R18 -> #REF!
B19: RevPAR | D19: =#REF! -> #REF! | E19: =D19/F19 -> #REF! | F19: ='PL Summary'!#REF! -> #REF! | G19: 1 | H19: ='PL Summary'!#REF! -> #REF! | I19: =H19/F19 -> #REF! | J19: ='PL Summary'!#REF! -> #REF! | K19: =J19/L19 -> #REF! | L19: ='PL Summary'!#REF! -> #REF! | M19: 1 | N19: ='PL Summary'!#REF! -> #REF! | O19: =N19/L19 -> #REF! | P19: =#REF!/P9 -> #REF! | Q19: =(D19-P19)/P19 -> #REF! | R19: =#REF!/R9 -> #REF! | S19: =(J19-R19)/R19 -> #REF!
B21: 4 | C21: REVENUE
B22: 41 | C22: Revenue - Department
B23: 411 | C23: Room Revenue* | D23: =D24+D29+D42+D49 -> 0 | E23: =E24+E29+E42+E49 -> 0 | F23: =F24+F29+F42+F49 -> 0 | G23: =G24+G29+G42+G49 -> 0 | H23: =H24+H29+H42+H49 -> 0 | I23: =I24+I29+I42+I49 -> 0 | J23: =J24+J29+J42+J49 -> 0 | K23: =K24+K29+K42+K49 -> 0 | ... N23: =N24+N29+N42+N49 -> 0
B24: 41101 | C24: Room Revenue | D24: =D25-D27 -> 0 | E24: =E25-E27 -> 0 | F24: =F25-F27 -> 0 | G24: =G25-G27 -> 0 | H24: =H25-H27 -> 0 | I24: =I25-I27 -> 0 | J24: =J25-J27 -> 0 | K24: =K25-K27 -> 0 | ... N24: =N25-N27 -> 0
B25: 41101001 | C25: RM - Room Revenue | H25: =D25-F25 -> 0 | N25: =J25-L25 -> 0
B26: 41101002 | C26: RM - Other Revenue | H26: =D26-F26 -> 0 | N26: =J26-L26 -> 0
B27: 41101003 | C27: RM - Room Discount & Allowances | H27: =D27-F27 -> 0 | N27: =J27-L27 -> 0
B28: 412 | C28: Food & Beverage Revenue
B29: 41201 | C29: Restaurant & Bar Revenue | D29: =SUM(D30:D35) -> 0 | E29: =SUM(E30:E35) -> 0 | F29: =SUM(F30:F35) -> 0 | G29: =SUM(G30:G35) -> 0 | H29: =SUM(H30:H35) -> 0 | I29: =SUM(I30:I35) -> 0 | J29: =SUM(J30:J35) -> 0 | L29: =SUM(L30:L35) -> 0 | M29: =SUM(M30:M35) -> 0 | N29: =SUM(N30:N35) -> 0
B30: 41201001 | C30: RB - Food Revenue | H30: =D30-F30 -> 0 | N30: =J30-L30 -> 0
B31: 41201002 | C31: RB - Beverage Revenue | H31: =D31-F31 -> 0 | N31: =J31-L31 -> 0
B32: 41201003 | C32: RB - Breakfast Catering | H32: =D32-F32 -> 0 | N32: =J32-L32 -> 0
B33: 41201004 | C33: RB - Other Revenue | H33: =D33-F33 -> 0 | N33: =J33-L33 -> 0
B34: 41201005 | C34: RB - Food Discount & Allowances | H34: =D34-F34 -> 0 | N34: =J34-L34 -> 0
B35: 41201005 | C35: RB - Beverage Discount & Allowances | H35: =D35-F35 -> 0 | N35: =J35-L35 -> 0
B36: 41202 | C36: Bar & Lounge Revenue | D36: =SUM(D37:D41) -> 0 | E36: =SUM(E37:E41) -> 0 | F36: =SUM(F37:F41) -> 0 | G36: =SUM(G37:G41) -> 0 | H36: =SUM(H37:H41) -> 0 | I36: =SUM(I37:I41) -> 0 | J36: =SUM(J37:J41) -> 0 | K36: =SUM(K37:K41) -> 0 | ... N36: =SUM(N37:N41) -> 0
B37: 41202001 | C37: BL - Food Revenue | H37: =D37-F37 -> 0 | N37: =J37-L37 -> 0
B38: 41202002 | C38: BL - Beverage Revenue | H38: =D38-F38 -> 0 | N38: =J38-L38 -> 0
B39: 41202003 | C39: BL - Other Revenue | H39: =D39-F39 -> 0 | N39: =J39-L39 -> 0
B40: 41202004 | C40: BL - Food Discount & Allowances | H40: =D40-F40 -> 0 | N40: =J40-L40 -> 0
B41: 41202005 | C41: BL - Beverage Discount & Allowances | H41: =D41-F41 -> 0 | N41: =J41-L41 -> 0
B42: 41203 | C42: Banquet & Meeting Package Revenue | D42: =SUM(D43:D47) -> 0 | E42: =SUM(E43:E47) -> 0 | F42: =SUM(F43:F47) -> 0 | G42: =SUM(G43:G47) -> 0 | H42: =SUM(H43:H47) -> 0 | I42: =SUM(I43:I47) -> 0 | J42: =SUM(J43:J47) -> 0 | K42: =SUM(K43:K47) -> 0 | ... N42: =SUM(N43:N47) -> 0
...

Sheet presentasi COA
A1: COA | F1: Description
A4: 1 | F4: ASSETS
A5: 1 | B5: 1 | F5: Current Assets
A6: 1 | B6: 1 | C6: 1 | F6: Cash and Cash Equivalent
A7: 1 | B7: 1 | C7: 1 | D7: 01 | F7: House Bank | G7: imprest fund, reimburst rutin per minggu atau tentukan saldo minimal, perhatikan lamanya reimburst, total saldo 30 juta
A8: 1 | B8: 1 | C8: 1 | D8: 01 | E8: 001 | F8: House Bank Main Safe | G8: petty cash di back office simpan di SDB
A9: 1 | B9: 1 | C9: 1 | D9: 01 | E9: 002 | F9: House Bank Front Office | G9: 1 FO 1-1.5 juta
A10: 1 | B10: 1 | C10: 1 | D10: 01 | E10: 003 | F10: House Bank FB | G10: 1 FB 750 ribu
A11: 1 | B11: 1 | C11: 1 | D11: 01 | E11: 004 | F11: House Bank Spa | G11: 1 spa 250 ribu
A12: 1 | B12: 1 | C12: 1 | D12: 01 | E12: 005 | F12: Front Office Cash Clearance | G12: harus nol, selisih antara kas dan bank dengan FO tunai
A13: 1 | B13: 1 | C13: 1 | D13: 01 | E13: 006 | F13: Back Office Cash Clearance | G13: harus nol, selisih antara kas dan bank dengan FO bank transfer
A14: 1 | B14: 1 | C14: 1 | D14: 02 | F14: Bank
A15: 1 | B15: 1 | C15: 1 | D15: 02 | E15: 001 | F15: Bank In ……………………………… | G15: BCA / Mandiri / …..
A16: 1 | B16: 1 | C16: 1 | D16: 02 | E16: 002 | F16: Bank In ……………………………… | G16: BCA / Mandiri / …..
A17: 1 | B17: 1 | C17: 1 | D17: 02 | E17: 003 | F17: Bank Out……………………………… | G17: BCA / Mandiri / …..
A18: 1 | B18: 1 | C18: 1 | D18: 02 | E18: 004 | F18: Bank Out……………………………… | G18: BCA / Mandiri / …..
A19: 1 | B19: 1 | C19: 1 | D19: 02 | E19: 005 | F19: Bank FF&E Reserve ……………………………… | G19: bank dana cadangan FF&E optional
A20: 1 | B20: 1 | C20: 1 | D20: 03 | F20: Time Deposit*
A21: 1 | B21: 1 | C21: 1 | D21: 03 | E21: 001 | F21: Time Deposit | G21: deposito di bank
A22: 1 | B22: 1 | C22: 2 | F22: Accounts Receivable
A23: 1 | B23: 1 | C23: 2 | D23: 01 | F23: A/R Trade
A24: 1 | B24: 1 | C24: 2 | D24: 01 | E24: 001 | F24: A/R Guest Ledger | G24: +/- guest deposit <=> guest check in, income audit journal
A25: 1 | B25: 1 | C25: 2 | D25: 01 | E25: 002 | F25: A/R City Ledger Travel | G25: potong PPh 23 2% NPWP dan 4% non NPWP, kalau LN minta perwakilan DN
A26: 1 | B26: 1 | C26: 2 | D26: 01 | E26: 003 | F26: A/R City Ledger Corporate | G26: perhatikan fasilitas credit, jangan ambil produksi kalau yang lama belum lunas
A27: 1 | B27: 1 | C27: 2 | D27: 01 | E27: 004 | F27: A/R City Ledger Government | G27: maksimum komisi 20% atau ditentukan lain oleh corporate
A28: 1 | B28: 1 | C28: 2 | D28: 01 | E28: 005 | F28: A/R Credit Card Visa BCA | G28: check 1.8%
A29: 1 | B29: 1 | C29: 2 | D29: 01 | E29: 006 | F29: A/R Credit Card Master BCA | G29: check 1.8%
A30: 1 | B30: 1 | C30: 2 | D30: 01 | E30: 007 | F30: A/R BCA Card | G30: check 0.9%
A31: 1 | B31: 1 | C31: 2 | D31: 01 | E31: 008 | F31: A/R Credit Card Visa Mandiri | G31: check 1.8%
A32: 1 | B32: 1 | C32: 2 | D32: 01 | E32: 009 | F32: A/R Credit Card Master Mandiri | G32: check 1.8%
A33: 1 | B33: 1 | C33: 2 | D33: 01 | E33: 010 | F33: A/R Credit Card Visa Other | G33: check 1.8%
A34: 1 | B34: 1 | C34: 2 | D34: 01 | E34: 011 | F34: A/R Credit Card Master Other | G34: check 1.8%
A35: 1 | B35: 1 | C35: 2 | D35: 01 | E35: 012 | F35: Pre Account Receiveable | G35: harus nol
A36: 1 | B36: 1 | C36: 2 | D36: 01 | E36: 013 | F36: Pre Credit Card | G36: harus nol
A37: 1 | B37: 1 | C37: 2 | D37: 03 | F37: A/R Affiliate
A38: 1 | B38: 1 | C38: 2 | D38: 03 | E38: 001 | F38: A/R Affiliated PT. …………………………… | G38: PT. Intiland Estrella (only) / PT. Owner
A39: 1 | B39: 1 | C39: 2 | D39: 03 | E39: 002 | F39: A/R Affiliated PT. …………………………… | G39: PT. Intiwhiz International
A40: 1 | B40: 1 | C40: 2 | D40: 04 | F40: Other Receivable
A41: 1 | B41: 1 | C41: 2 | D41: 04 | E41: 001 | F41: A/R Employee | G41: piutang ke karyawan
A42: 1 | B42: 1 | C42: 2 | D42: 04 | E42: 002 | F42: Notes Receivable | G42: cek dan giro yang kita terima
...

Sheet perubahan 11.11.14
I2: No COA Baru
H3: tambahan | I3: 8 | J3: 3 | N3: Interest Expense**
B4: No COA Lama | H4: tambahan | I4: 8 | J4: 3 | K4: 1 | N4: Interest Expense*
B5: 8 | C5: 1 | D5: 2 | E5: 04 | G5: Interest Expense | H5: menjadi | I5: 8 | J5: 3 | K5: 1 | L5: 01 | N5: Interest Expense
B6: 8 | C6: 1 | D6: 2 | E6: 04 | F6: 001 | G6: Interest Bank Loan (IDR) | H6: menjadi | I6: 8 | J6: 3 | K6: 1 | L6: 01 | M6: 001 | N6: Interest Bank Loan (IDR)
B7: 8 | C7: 1 | D7: 2 | E7: 04 | F7: 002 | G7: Interest Bank Loan (IDR) - Provision Cost | H7: menjadi | I7: 8 | J7: 3 | K7: 1 | L7: 01 | M7: 002 | N7: Interest Bank Loan (IDR) - Provision Cost
B8: 8 | C8: 1 | D8: 2 | E8: 04 | F8: 003 | G8: Interest Expense - Leased Assets | H8: menjadi | I8: 8 | J8: 3 | K8: 1 | L8: 01 | M8: 003 | N8: Interest Expense - Leased Assets
B9: 8 | C9: 3 | G9: Income Taxes*** | H9: menjadi | I9: 8 | J9: 4 | N9: Income Taxes***
B10: 8 | C10: 3 | D10: 1 | G10: Income Taxes** | H10: menjadi | I10: 8 | J10: 4 | K10: 1 | N10: Income Taxes**
B11: 8 | C11: 3 | D11: 1 | E11: 01 | G11: Income Taxes* | H11: menjadi | I11: 8 | J11: 4 | K11: 1 | L11: 01 | N11: Income Taxes*
B12: 8 | C12: 3 | D12: 1 | E12: 01 | F12: 001 | G12: Income Taxes | H12: menjadi | I12: 8 | J12: 4 | K12: 1 | L12: 01 | M12: 001 | N12: Income Taxes
